<!--
 * @Description: 
 * @version: 
 * @Author: hmlhml
 * @Date: 2021-06-08 17:30:44
 * @LastEditors: hmlhml
-->
## 一、错误类型

1、语法错误（SyntaxError）

```javascript
function a() {var a = }
Uncaught SyntaxError: Unexpected token '}'
```

2、类型错误（TypeError）

```javascript
var a; 
a();
Uncaught TypeError: a is not a function
```

3、范围错误（RangeError）

```javascript
var arr = new Array(-1)
Uncaught RangeError: Invalid array length
```

4、引用错误（ReferenceError）

```javascript
console.log(a) 
Uncaught ReferenceError: a is not defined
```

5、eval错误（EvalError）

6、URL错误（URIError）

```javascript
decodeURIComponent('%')
```

7、资源加载错误（Fails to load resource） 

```javascript
GET xxxx/1.jpg net::ERR_FILE_NOT_FOUND
ET file://baidu.com/test.js net::ERR_INVALID_URL
```
触发条件：`<img><script><style><video>`等标签加载出错时触发  
监听方式：标签的`onerror`事件、全局绑定`onerror`事件

```html
<body>
    <img src="1.jpg" alt="" onerror="loadFail()" />
    <script>
      // 标签的onerror事件
        function loadFail() {
          console.log('加载错误');
        }
        // 全局绑定onerror事件
        window.addEventListener('error',function(e){
            console.log(e)
        },true)
    </script>
  </body>
```


## 二、前端错误监控解决方案

### 1、错误分类
#### a）运行时错误  
这个错误往往是我们在代码书写时造成的，比如语法错误、逻辑错误，这样的错误通常在测试阶段就会被发现，但是也可能存在“漏网之鱼”。

#### b）资源加载错误  
这个错误通常是找不到文件或者是文件加载超时造成的。


### 2、错误捕获
#### a）代码错误捕获

try...catch...
```javascript
try { 
  // 运行可能出错的代码
} catch (e){ 
 // 捕获错误
}
```

windown.onerror
```javascript
window.onerror=funcetion(e) { 
  // 捕获错误
}
```
#### b）资源加载错误捕获

Object.onerror
```javascript
var img = document.getElementById('#img');
img.onerror = function () {
    // 捕获错误
    console.log("tagname", e.srcElement.tagName);
    console.log("src", e.srcElement.src);
}
```

利用window的Error事件代理,但是需要注意的是error事件是不冒泡的，我们可以使用事件捕获进行代理。
```javascript
window.addEventListener("error",function(e){
    // 捕获错误
    // 通过e.srcElement来判断网络错误事件发生的元素
    const srcElement = e.srcElement;
    if (srcElement === window) {
        // 全局错误
        console.log("全局错误");
        console.log("message", e.message);
    } else {
        // 元素错误，比如引用资源报错
        console.log("元素错误");
        console.log("tagname", srcElement.tagName);
        console.log("src", srcElement.src);
    }
    console.log("onerror捕获网络请求错误", e); // 捕获错误
},true);
```

#### c）跨域文件错误
引用外链不同源js文件报错，onerror只会提示`Script error`，无法精确到指定文件和行数  
 
* 跨域文件设置
```javascript
<script crossorigin src="http://www.lmj.com/demo/crossoriginAttribute/error.js"></script>
```

* 服务端设置：
```javascript
header('Access-Control-Allow-Origin: *');

```

### 3、错误上报
#### a) Ajax上传
Ajax上报就是在上文注释错误捕获的地方发起Ajax请求，来向服务器发送错误信息。

#### b) 利用Image对象发送信息
```javascript
(new Image()).src="http://post.error.com?data=xxx"
```

**注意：压缩js的错误定位**  
> 在线上的代码都是经过压缩的，可以捕捉到的错误为压缩后的行数和变量，可以通过node提供的source-map模块来定位上报错误信息对应源文件错误的行号



## 三、js异常捕获
### 1、无法捕获的情况
#### a）异步任务

##### 情况1: 宏任务的回调函数中的错误无法捕获
```javascript
// 异步任务
const task = () => {
    setTimeout(() => {
        throw new Error("async error");
    }, 1000);
};
// 主任务
function main() {
    try {
        task();
    } catch (e) {
        console.log(e, "err");
        console.log("continue...");
    }
} 
// `Uncaught Error: async error`    
```
**说明：**  
异步任务由 eventloop 加入任务队列，并取出入栈(js 主进程)执行，而当 task 取出执行的时候， main 的栈已经退出了，也就是上下文环境已经改变，所以 main 无法捕获 task 的错误。


**解决：**  可通过`window.onerror`来捕获该异常

##### 情况2: 微任务（promise）的回调

```javascript
// 返回一个 promise 对象
const promiseFetch = () =>
    new Promise((reslove) => {
        reslove();
    });

function main() {
    try {
        // 回调函数里抛出错误
        promiseFetch().then(() => {
            throw new Error("err");
        });
    } catch (e) {
        console.log(e, "eeee");
        console.log("continue");
    }
}

main();
`Uncaught (in promise) Error: err`
```

**说明：**  
promise 的任务，也就是 then 里面的回调函数，抛出错误同样也无法 catch。因为微任务队列是在两个 task 之间清空的，所以 then 入栈的时候，main 函数也已经出栈了。

**解决：**  可通过`window.onunhandledrejection`来捕获盖异常

##### 情况3: 并不是回调函数无法 `try catch`

```javascript
// 定义一个 fn，参数是函数。
const fn = (cb: () => void) => {
    cb();
};

function main() {
    try {
        // 传入 callback，fn 执行会调用，并抛出错误。
        fn(() => {
            throw new Error('123');
        })
    } catch(e) {
        console.log('error');
    }
}
main();
```

**总结：**  
* try...catch...可以捕获同步代码，不可以捕获一步任务
* 普通异步回调可通过`window.onerror`捕获
* promise异步回调可通过`window.onunhandledrejection`捕获


### 2、promise 的异常捕获

#### a）构造函数

```javascript
function main1() {
    try {
        new Promise(() => {
            throw new Error('promise1 error')
        })
    } catch(e) {
        console.log(e.message);
    }
}

function main2() {
    try {
        Promise.reject('promise2 error');
    } catch(e) {
        console.log(e.message);
    }
}
```

**说明**  
以上两个 try catch 都不能捕获到 error，因为 `promise` 内部的错误不会冒泡出来，而是被 `promise` 吃掉了，只有通过 `promise.catch` 才可以捕获，所以用 `Promise` 一定要写 `catch` 啊。



然后我们再来看一下使用 promise.catch 的两段代码：
```javascript
// reject
const p1 = new Promise((reslove, reject) => {
    if (1) {
        reject();
    }
});
p1.catch((e) => console.log("p1 error"));


// throw new Error
const p2 = new Promise((reslove, reject) => {
    if (1) {
        throw new Error("p2 error");
    }
});
p2.catch((e) => console.log("p2 error"));
```

**说明**  
promise 内部的无论是 reject 或者 throw new Error，都可以通过 catch 回调捕获。

**注意**    
promise 的微任务指的是 then 的回调，而此处是 Promise 构造函数传入的第一个参数，new Promise 是同步执行的。


#### b）then

```javascript
function main3() {
  Promise.resolve(true).then(() => {
    try {
      throw new Error('then');
    } catch(e) {
      return e;
    }
  }).then(e => console.log(e.message));
}
```

**说明**  
只能是在回调函数内部 catch 错误，并把错误信息返回，error 会传递到下一个 then 的回调。

#### c）构造函数捕获异步错误

```javascript
 
const p3 = () =>  new Promise((reslove, reject) => {
  setTimeout(() => {
    reject('async error');
  })
});
 
function main3() {
  p3().catch(e => console.log(e));
}
main3();
```
**说明**  
把异步操作用 Promise 包装，通过内部判断，把错误 reject，在外面通过 promise.catch 捕获。

### 3、async/await的异常捕获

```javascript
const fetchFailure = () => new Promise((resolve, reject) => {
  setTimeout(() => {// 模拟请求
    if(1) reject('fetch failure...');
  })
})
 
async function main () {
  try {
    const res = await fetchFailure(); // 1
    console.log(res, 'res');  // 2
  } catch(e) {
    console.log(e, 'e.message'); // 3
  }
}
main();
```
**说明**  
1->2: 异步是通过 Promise.then() 控制的  
1中reject之后，会向上冒泡，执行内部的throw，然后catch会执行

### 总结
**try catch finally**
* 只能捕获运行时的错误，无法捕获语法错误，可以拿到出错的信息，堆栈，出错的文件、行号、列号。  
* 语句标记要尝试的语句块，并指定一个出现异常时抛出的响应。  
* 嵌套`try…catch…finally`  
（1）如果try块中抛出错误，那么try块中错误抛出语句后面的其他语句均不会执行；  
（2）不管try块中是否抛出错误，finally块语句一定会被执行；  
（3）内层try块抛出的错误会被对应内层的catch块捕获，如果不存在对应的内层catch块，那么会被抛到上一层，被上一层的catch块捕获，如果还没有被捕获，那么继续抛到上一层，直到最外层。


**window.onerror**
* 可以捕捉语法错误，也可以捕捉运行时错误，可以拿到出错的信息，堆栈，出错的文件、行号、列号。  
* 只要在当前window执行的Js脚本出错都会捕捉到，通过`window.onerror`可以实现前端的错误监控。  
* 出于安全方面的考虑，当加载自不同域的脚本中发生语法错误时，语法错误的细节将不会报告。  




